[2024-06-11 00:41:30,694: INFO: main: >>>>>> stage Data Ingestion stage started <<<<<<]
[2024-06-11 00:41:30,701: INFO: common: yaml file: config\config.yaml loaded successfully]
[2024-06-11 00:41:30,707: INFO: common: yaml file: params.yaml loaded successfully]
[2024-06-11 00:41:30,708: INFO: common: created directory at: artifacts]
[2024-06-11 00:41:30,709: INFO: common: created directory at: artifacts/data_ingestion]
[2024-06-11 00:41:31,932: INFO: data_ingestion: artifacts/data_ingestion/data.zip download! with following info: 
Server: GitHub.com
Date: Mon, 10 Jun 2024 19:11:30 GMT
Content-Type: text/html; charset=utf-8
Vary: X-PJAX, X-PJAX-Container, Turbo-Visit, Turbo-Frame, Accept-Encoding, Accept, X-Requested-With
ETag: W/"983aeab5f880f945e332b4d06f8dabad"
Cache-Control: max-age=0, private, must-revalidate
Strict-Transport-Security: max-age=31536000; includeSubdomains; preload
X-Frame-Options: deny
X-Content-Type-Options: nosniff
X-XSS-Protection: 0
Referrer-Policy: no-referrer-when-downgrade
Content-Security-Policy: default-src 'none'; base-uri 'self'; child-src github.com/assets-cdn/worker/ gist.github.com/assets-cdn/worker/; connect-src 'self' uploads.github.com www.githubstatus.com collector.github.com raw.githubusercontent.com api.github.com github-cloud.s3.amazonaws.com github-production-repository-file-5c1aeb.s3.amazonaws.com github-production-upload-manifest-file-7fdce7.s3.amazonaws.com github-production-user-asset-6210df.s3.amazonaws.com api.githubcopilot.com objects-origin.githubusercontent.com copilot-proxy.githubusercontent.com/v1/engines/github-completion/completions *.actions.githubusercontent.com wss://*.actions.githubusercontent.com productionresultssa0.blob.core.windows.net/ productionresultssa1.blob.core.windows.net/ productionresultssa2.blob.core.windows.net/ productionresultssa3.blob.core.windows.net/ productionresultssa4.blob.core.windows.net/ productionresultssa5.blob.core.windows.net/ productionresultssa6.blob.core.windows.net/ productionresultssa7.blob.core.windows.net/ productionresultssa8.blob.core.windows.net/ productionresultssa9.blob.core.windows.net/ productionresultssa10.blob.core.windows.net/ productionresultssa11.blob.core.windows.net/ productionresultssa12.blob.core.windows.net/ productionresultssa13.blob.core.windows.net/ productionresultssa14.blob.core.windows.net/ productionresultssa15.blob.core.windows.net/ productionresultssa16.blob.core.windows.net/ productionresultssa17.blob.core.windows.net/ productionresultssa18.blob.core.windows.net/ productionresultssa19.blob.core.windows.net/ github-production-repository-image-32fea6.s3.amazonaws.com github-production-release-asset-2e65be.s3.amazonaws.com insights.github.com wss://alive.github.com; font-src github.githubassets.com; form-action 'self' github.com gist.github.com copilot-workspace.githubnext.com objects-origin.githubusercontent.com; frame-ancestors 'none'; frame-src viewscreen.githubusercontent.com notebooks.githubusercontent.com; img-src 'self' data: github.githubassets.com media.githubusercontent.com camo.githubusercontent.com identicons.github.com avatars.githubusercontent.com github-cloud.s3.amazonaws.com objects.githubusercontent.com secured-user-images.githubusercontent.com/ user-images.githubusercontent.com/ private-user-images.githubusercontent.com opengraph.githubassets.com github-production-user-asset-6210df.s3.amazonaws.com customer-stories-feed.github.com spotlights-feed.github.com objects-origin.githubusercontent.com *.githubusercontent.com; manifest-src 'self'; media-src github.com user-images.githubusercontent.com/ secured-user-images.githubusercontent.com/ private-user-images.githubusercontent.com github-production-user-asset-6210df.s3.amazonaws.com gist.github.com; script-src github.githubassets.com; style-src 'unsafe-inline' github.githubassets.com; upgrade-insecure-requests; worker-src github.com/assets-cdn/worker/ gist.github.com/assets-cdn/worker/
Set-Cookie: _gh_sess=08Bb4shTF3qTXfMQLGdyv6jSEpJSFLDuNsSVXan7SlPunYAtC5uXBZ0nOVJ1f6BwaAS2Semon9lkwU8XIdTbPe7CpqkSEfxNoc%2FWaY078AlZ2zNF6ftzC6gHao77uMGSZ3YfJ00gKJKtJo3XfpEhbl%2BKEi2En%2FwP9ewgd8KCBYXiA3vc3YZGaeQn5PdS1ck5O2MCJ7tsZ%2BlhOGJSBfq%2FtKP6mjuw7JScWRQUBTkxiD4zzzby%2FhKg%2FR9WWgZVnmR0iRCTbZofCgwEggjCXDDGmA%3D%3D--qsZNk5Ar64fSgZy5--omAKmG9QCIX%2BC6riRvsnjg%3D%3D; Path=/; HttpOnly; Secure; SameSite=Lax
Set-Cookie: _octo=GH1.1.423827654.1718046690; Path=/; Domain=github.com; Expires=Tue, 10 Jun 2025 19:11:30 GMT; Secure; SameSite=Lax
Set-Cookie: logged_in=no; Path=/; Domain=github.com; Expires=Tue, 10 Jun 2025 19:11:30 GMT; HttpOnly; Secure; SameSite=Lax
Accept-Ranges: bytes
Transfer-Encoding: chunked
X-GitHub-Request-Id: 99FD:10E5A9:D067E:EBBD8:66674FE1
connection: close

]
[2024-06-11 00:41:32,013: ERROR: main: File is not a zip file]
Traceback (most recent call last):
  File "c:\Users\Anoop Maurya\Documents\GitHub\End-To-End-NLP-Project-Implementation-With-Deployment-Github-Action\main.py", line 8, in <module>
    data_ingestion.main()
  File "c:\users\anoop maurya\documents\github\end-to-end-nlp-project-implementation-with-deployment-github-action\src\textSummarizer\pipeline\stage_01_data_ingestion.py", line 15, in main
    data_ingestion.extract_zip_file()
  File "c:\users\anoop maurya\documents\github\end-to-end-nlp-project-implementation-with-deployment-github-action\src\textSummarizer\conponents\data_ingestion.py", line 36, in extract_zip_file
    with zipfile.ZipFile(self.config.local_data_file, 'r') as zip_ref:
         ^^^^^^^^^^^^^^^^^^^^^^^^^^^^^^^^^^^^^^^^^^^^^^^^^
  File "C:\ProgramData\anaconda3\Lib\zipfile.py", line 1302, in __init__
    self._RealGetContents()
  File "C:\ProgramData\anaconda3\Lib\zipfile.py", line 1369, in _RealGetContents
    raise BadZipFile("File is not a zip file")
zipfile.BadZipFile: File is not a zip file
[2024-06-11 00:42:39,353: INFO: main: >>>>>> stage Data Ingestion stage started <<<<<<]
[2024-06-11 00:42:39,355: INFO: common: yaml file: config\config.yaml loaded successfully]
[2024-06-11 00:42:39,356: INFO: common: yaml file: params.yaml loaded successfully]
[2024-06-11 00:42:39,357: INFO: common: created directory at: artifacts]
[2024-06-11 00:42:39,358: INFO: common: created directory at: artifacts/data_ingestion]
[2024-06-11 00:42:39,359: INFO: data_ingestion: File already exists of size: ~ 264 KB]
[2024-06-11 00:42:39,359: ERROR: main: File is not a zip file]
Traceback (most recent call last):
  File "c:\Users\Anoop Maurya\Documents\GitHub\End-To-End-NLP-Project-Implementation-With-Deployment-Github-Action\main.py", line 8, in <module>
    data_ingestion.main()
  File "c:\users\anoop maurya\documents\github\end-to-end-nlp-project-implementation-with-deployment-github-action\src\textSummarizer\pipeline\stage_01_data_ingestion.py", line 15, in main
    data_ingestion.extract_zip_file()
  File "c:\users\anoop maurya\documents\github\end-to-end-nlp-project-implementation-with-deployment-github-action\src\textSummarizer\conponents\data_ingestion.py", line 36, in extract_zip_file
    with zipfile.ZipFile(self.config.local_data_file, 'r') as zip_ref:
         ^^^^^^^^^^^^^^^^^^^^^^^^^^^^^^^^^^^^^^^^^^^^^^^^^
  File "C:\ProgramData\anaconda3\Lib\zipfile.py", line 1302, in __init__
    self._RealGetContents()
  File "C:\ProgramData\anaconda3\Lib\zipfile.py", line 1369, in _RealGetContents
    raise BadZipFile("File is not a zip file")
zipfile.BadZipFile: File is not a zip file
[2024-06-11 00:43:53,644: INFO: main: >>>>>> stage Data Ingestion stage started <<<<<<]
[2024-06-11 00:43:53,651: INFO: common: yaml file: config\config.yaml loaded successfully]
[2024-06-11 00:43:53,652: INFO: common: yaml file: params.yaml loaded successfully]
[2024-06-11 00:43:53,653: INFO: common: created directory at: artifacts]
[2024-06-11 00:43:53,653: INFO: common: created directory at: artifacts/data_ingestion]
[2024-06-11 00:43:53,653: INFO: data_ingestion: File already exists of size: ~ 264 KB]
[2024-06-11 00:43:53,654: ERROR: main: File is not a zip file]
Traceback (most recent call last):
  File "c:\Users\Anoop Maurya\Documents\GitHub\End-To-End-NLP-Project-Implementation-With-Deployment-Github-Action\main.py", line 8, in <module>
    data_ingestion.main()
  File "c:\users\anoop maurya\documents\github\end-to-end-nlp-project-implementation-with-deployment-github-action\src\textSummarizer\pipeline\stage_01_data_ingestion.py", line 15, in main
    data_ingestion.extract_zip_file()
  File "c:\users\anoop maurya\documents\github\end-to-end-nlp-project-implementation-with-deployment-github-action\src\textSummarizer\conponents\data_ingestion.py", line 36, in extract_zip_file
    with zipfile.ZipFile(self.config.local_data_file, 'r') as zip_ref:
         ^^^^^^^^^^^^^^^^^^^^^^^^^^^^^^^^^^^^^^^^^^^^^^^^^
  File "C:\ProgramData\anaconda3\Lib\zipfile.py", line 1302, in __init__
    self._RealGetContents()
  File "C:\ProgramData\anaconda3\Lib\zipfile.py", line 1369, in _RealGetContents
    raise BadZipFile("File is not a zip file")
zipfile.BadZipFile: File is not a zip file
[2024-06-11 00:44:06,778: INFO: main: >>>>>> stage Data Ingestion stage started <<<<<<]
[2024-06-11 00:44:06,779: INFO: common: yaml file: config\config.yaml loaded successfully]
[2024-06-11 00:44:06,780: INFO: common: yaml file: params.yaml loaded successfully]
[2024-06-11 00:44:06,780: INFO: common: created directory at: artifacts]
[2024-06-11 00:44:06,780: INFO: common: created directory at: artifacts/data_ingestion]
[2024-06-11 00:44:06,781: INFO: data_ingestion: File already exists of size: ~ 264 KB]
[2024-06-11 00:44:06,781: ERROR: main: File is not a zip file]
Traceback (most recent call last):
  File "c:\Users\Anoop Maurya\Documents\GitHub\End-To-End-NLP-Project-Implementation-With-Deployment-Github-Action\main.py", line 8, in <module>
    data_ingestion.main()
  File "c:\users\anoop maurya\documents\github\end-to-end-nlp-project-implementation-with-deployment-github-action\src\textSummarizer\pipeline\stage_01_data_ingestion.py", line 15, in main
    data_ingestion.extract_zip_file()
  File "c:\users\anoop maurya\documents\github\end-to-end-nlp-project-implementation-with-deployment-github-action\src\textSummarizer\conponents\data_ingestion.py", line 36, in extract_zip_file
    with zipfile.ZipFile(self.config.local_data_file, 'r') as zip_ref:
         ^^^^^^^^^^^^^^^^^^^^^^^^^^^^^^^^^^^^^^^^^^^^^^^^^
  File "C:\ProgramData\anaconda3\Lib\zipfile.py", line 1302, in __init__
    self._RealGetContents()
  File "C:\ProgramData\anaconda3\Lib\zipfile.py", line 1369, in _RealGetContents
    raise BadZipFile("File is not a zip file")
zipfile.BadZipFile: File is not a zip file
[2024-06-11 00:44:33,482: INFO: main: >>>>>> stage Data Ingestion stage started <<<<<<]
[2024-06-11 00:44:33,483: INFO: common: yaml file: config\config.yaml loaded successfully]
[2024-06-11 00:44:33,484: INFO: common: yaml file: params.yaml loaded successfully]
[2024-06-11 00:44:33,485: INFO: common: created directory at: artifacts]
[2024-06-11 00:44:33,486: INFO: common: created directory at: artifacts/data_ingestion]
[2024-06-11 00:44:36,194: INFO: data_ingestion: artifacts/data_ingestion/data.zip download! with following info: 
Connection: close
Content-Length: 7903594
Cache-Control: max-age=300
Content-Security-Policy: default-src 'none'; style-src 'unsafe-inline'; sandbox
Content-Type: application/zip
ETag: "dbc016a060da18070593b83afff580c9b300f0b6ea4147a7988433e04df246ca"
Strict-Transport-Security: max-age=31536000
X-Content-Type-Options: nosniff
X-Frame-Options: deny
X-XSS-Protection: 1; mode=block
X-GitHub-Request-Id: 68B4:F0C41:65765:7E9E5:66675099
Accept-Ranges: bytes
Date: Mon, 10 Jun 2024 19:14:34 GMT
Via: 1.1 varnish
X-Served-By: cache-del21732-DEL
X-Cache: MISS
X-Cache-Hits: 0
X-Timer: S1718046874.828609,VS0,VE715
Vary: Authorization,Accept-Encoding,Origin
Access-Control-Allow-Origin: *
Cross-Origin-Resource-Policy: cross-origin
X-Fastly-Request-ID: 96f6e60608ed990d78bc629eef26692ab0633571
Expires: Mon, 10 Jun 2024 19:19:34 GMT
Source-Age: 0

]
[2024-06-11 00:44:36,444: INFO: main: >>>>>> stage Data Ingestion stage completed <<<<<<

x==========x]
[2024-06-11 10:10:29,234: INFO: main: >>>>>> stage Data Ingestion stage started <<<<<<]
[2024-06-11 10:10:29,246: INFO: common: yaml file: config\config.yaml loaded successfully]
[2024-06-11 10:10:29,247: INFO: common: yaml file: params.yaml loaded successfully]
[2024-06-11 10:10:29,248: INFO: common: created directory at: artifacts]
[2024-06-11 10:10:29,248: INFO: common: created directory at: artifacts/data_ingestion]
[2024-06-11 10:10:34,071: INFO: data_ingestion: artifacts/data_ingestion/data.zip download! with following info: 
Connection: close
Content-Length: 7903594
Cache-Control: max-age=300
Content-Security-Policy: default-src 'none'; style-src 'unsafe-inline'; sandbox
Content-Type: application/zip
ETag: "dbc016a060da18070593b83afff580c9b300f0b6ea4147a7988433e04df246ca"
Strict-Transport-Security: max-age=31536000
X-Content-Type-Options: nosniff
X-Frame-Options: deny
X-XSS-Protection: 1; mode=block
X-GitHub-Request-Id: 1D31:13D506:2222C:35CF2:6667D53D
Accept-Ranges: bytes
Date: Tue, 11 Jun 2024 04:40:30 GMT
Via: 1.1 varnish
X-Served-By: cache-del21731-DEL
X-Cache: MISS
X-Cache-Hits: 0
X-Timer: S1718080830.882647,VS0,VE727
Vary: Authorization,Accept-Encoding,Origin
Access-Control-Allow-Origin: *
Cross-Origin-Resource-Policy: cross-origin
X-Fastly-Request-ID: 9ccf5e8375170395ede23cb26bc5e13e3839cbd8
Expires: Tue, 11 Jun 2024 04:45:30 GMT
Source-Age: 0

]
[2024-06-11 10:10:34,280: INFO: main: >>>>>> stage Data Ingestion stage completed <<<<<<

x==========x]
[2024-06-11 10:10:34,281: INFO: main: >>>>>> stage Data Validation stage started <<<<<<]
[2024-06-11 10:10:34,283: INFO: common: yaml file: config\config.yaml loaded successfully]
[2024-06-11 10:10:34,284: INFO: common: yaml file: params.yaml loaded successfully]
[2024-06-11 10:10:34,285: INFO: common: created directory at: artifacts]
[2024-06-11 10:10:34,285: INFO: common: created directory at: artifacts/data_validation]
[2024-06-11 10:10:34,286: ERROR: main: name 'DataValiadtion' is not defined]
Traceback (most recent call last):
  File "c:\Users\Anoop Maurya\Documents\GitHub\End-To-End-NLP-Project-Implementation-With-Deployment-Github-Action\main.py", line 22, in <module>
    data_validation.main()
  File "c:\users\anoop maurya\documents\github\end-to-end-nlp-project-implementation-with-deployment-github-action\src\textSummarizer\pipeline\stage_02_data_validation.py", line 13, in main
    data_validation = DataValiadtion(config=data_validation_config)
                      ^^^^^^^^^^^^^^
NameError: name 'DataValiadtion' is not defined
[2024-06-11 10:11:03,752: INFO: main: >>>>>> stage Data Ingestion stage started <<<<<<]
[2024-06-11 10:11:03,754: INFO: common: yaml file: config\config.yaml loaded successfully]
[2024-06-11 10:11:03,755: INFO: common: yaml file: params.yaml loaded successfully]
[2024-06-11 10:11:03,755: INFO: common: created directory at: artifacts]
[2024-06-11 10:11:03,756: INFO: common: created directory at: artifacts/data_ingestion]
[2024-06-11 10:11:03,756: INFO: data_ingestion: File already exists of size: ~ 7718 KB]
[2024-06-11 10:11:03,908: INFO: main: >>>>>> stage Data Ingestion stage completed <<<<<<

x==========x]
[2024-06-11 10:11:03,909: INFO: main: >>>>>> stage Data Validation stage started <<<<<<]
[2024-06-11 10:11:03,912: INFO: common: yaml file: config\config.yaml loaded successfully]
[2024-06-11 10:11:03,913: INFO: common: yaml file: params.yaml loaded successfully]
[2024-06-11 10:11:03,913: INFO: common: created directory at: artifacts]
[2024-06-11 10:11:03,913: INFO: common: created directory at: artifacts/data_validation]
[2024-06-11 10:11:03,916: INFO: main: >>>>>> stage Data Validation stage completed <<<<<<

x==========x]
[2024-06-11 10:21:33,510: INFO: utils: NumExpr defaulting to 4 threads.]
[2024-06-11 10:21:35,690: INFO: main: >>>>>> stage Data Ingestion stage started <<<<<<]
[2024-06-11 10:21:35,695: INFO: common: yaml file: config\config.yaml loaded successfully]
[2024-06-11 10:21:35,696: INFO: common: yaml file: params.yaml loaded successfully]
[2024-06-11 10:21:35,697: INFO: common: created directory at: artifacts]
[2024-06-11 10:21:35,697: INFO: common: created directory at: artifacts/data_ingestion]
[2024-06-11 10:21:35,698: INFO: data_ingestion: File already exists of size: ~ 7718 KB]
[2024-06-11 10:21:35,840: INFO: main: >>>>>> stage Data Ingestion stage completed <<<<<<

x==========x]
[2024-06-11 10:21:35,840: INFO: main: >>>>>> stage Data Validation stage started <<<<<<]
[2024-06-11 10:21:35,842: INFO: common: yaml file: config\config.yaml loaded successfully]
[2024-06-11 10:21:35,843: INFO: common: yaml file: params.yaml loaded successfully]
[2024-06-11 10:21:35,844: INFO: common: created directory at: artifacts]
[2024-06-11 10:21:35,844: INFO: common: created directory at: artifacts/data_validation]
[2024-06-11 10:21:35,846: INFO: main: >>>>>> stage Data Validation stage completed <<<<<<

x==========x]
[2024-06-11 10:21:35,846: INFO: main: >>>>>> stage Data Transformation stage started <<<<<<]
[2024-06-11 10:21:35,851: INFO: common: yaml file: config\config.yaml loaded successfully]
[2024-06-11 10:21:35,852: INFO: common: yaml file: params.yaml loaded successfully]
[2024-06-11 10:21:35,852: INFO: common: created directory at: artifacts]
[2024-06-11 10:21:35,856: INFO: common: created directory at: artifacts/data_transformation]
[2024-06-11 10:21:42,731: ERROR: main: Protocol not known: artifacts/data_ingestion/samsum_dataset]
Traceback (most recent call last):
  File "c:\Users\Anoop Maurya\Documents\GitHub\End-To-End-NLP-Project-Implementation-With-Deployment-Github-Action\main.py", line 34, in <module>
    data_transformation.main()
  File "c:\users\anoop maurya\documents\github\end-to-end-nlp-project-implementation-with-deployment-github-action\src\textSummarizer\pipeline\stage_03_data_transformation.py", line 14, in main
    data_transformation.convert()
  File "c:\users\anoop maurya\documents\github\end-to-end-nlp-project-implementation-with-deployment-github-action\src\textSummarizer\components\data_transformation.py", line 30, in convert
    dataset_samsum = load_from_disk(self.config.data_path)
                     ^^^^^^^^^^^^^^^^^^^^^^^^^^^^^^^^^^^^^
  File "C:\ProgramData\anaconda3\Lib\site-packages\datasets\load.py", line 1892, in load_from_disk
    return DatasetDict.load_from_disk(dataset_path, keep_in_memory=keep_in_memory, storage_options=storage_options)
           ^^^^^^^^^^^^^^^^^^^^^^^^^^^^^^^^^^^^^^^^^^^^^^^^^^^^^^^^^^^^^^^^^^^^^^^^^^^^^^^^^^^^^^^^^^^^^^^^^^^^^^^^
  File "C:\ProgramData\anaconda3\Lib\site-packages\datasets\dataset_dict.py", line 1319, in load_from_disk
    dataset_dict[k] = Dataset.load_from_disk(
                      ^^^^^^^^^^^^^^^^^^^^^^^
  File "C:\ProgramData\anaconda3\Lib\site-packages\datasets\arrow_dataset.py", line 1627, in load_from_disk
    fs_token_paths = fsspec.get_fs_token_paths(dataset_path, storage_options=storage_options)
                     ^^^^^^^^^^^^^^^^^^^^^^^^^^^^^^^^^^^^^^^^^^^^^^^^^^^^^^^^^^^^^^^^^^^^^^^^
  File "C:\Users\Anoop Maurya\AppData\Roaming\Python\Python311\site-packages\fsspec\core.py", line 648, in get_fs_token_paths
    chain = _un_chain(urlpath0, storage_options or {})
            ^^^^^^^^^^^^^^^^^^^^^^^^^^^^^^^^^^^^^^^^^^
  File "C:\Users\Anoop Maurya\AppData\Roaming\Python\Python311\site-packages\fsspec\core.py", line 344, in _un_chain
    cls = get_filesystem_class(protocol)
          ^^^^^^^^^^^^^^^^^^^^^^^^^^^^^^
  File "C:\Users\Anoop Maurya\AppData\Roaming\Python\Python311\site-packages\fsspec\registry.py", line 239, in get_filesystem_class
    raise ValueError(f"Protocol not known: {protocol}")
ValueError: Protocol not known: artifacts/data_ingestion/samsum_dataset
[2024-06-11 10:28:36,197: INFO: utils: NumExpr defaulting to 4 threads.]
[2024-06-11 10:28:37,152: INFO: main: >>>>>> stage Data Ingestion stage started <<<<<<]
[2024-06-11 10:28:37,154: INFO: common: yaml file: config\config.yaml loaded successfully]
[2024-06-11 10:28:37,155: INFO: common: yaml file: params.yaml loaded successfully]
[2024-06-11 10:28:37,155: INFO: common: created directory at: artifacts]
[2024-06-11 10:28:37,156: INFO: common: created directory at: artifacts/data_ingestion]
[2024-06-11 10:28:37,156: INFO: data_ingestion: File already exists of size: ~ 7718 KB]
[2024-06-11 10:28:37,283: INFO: main: >>>>>> stage Data Ingestion stage completed <<<<<<

x==========x]
[2024-06-11 10:28:37,283: INFO: main: >>>>>> stage Data Validation stage started <<<<<<]
[2024-06-11 10:28:37,285: INFO: common: yaml file: config\config.yaml loaded successfully]
[2024-06-11 10:28:37,286: INFO: common: yaml file: params.yaml loaded successfully]
[2024-06-11 10:28:37,287: INFO: common: created directory at: artifacts]
[2024-06-11 10:28:37,287: INFO: common: created directory at: artifacts/data_validation]
[2024-06-11 10:28:37,290: INFO: main: >>>>>> stage Data Validation stage completed <<<<<<

x==========x]
[2024-06-11 10:28:37,290: INFO: main: >>>>>> stage Data Transformation stage started <<<<<<]
[2024-06-11 10:28:37,292: INFO: common: yaml file: config\config.yaml loaded successfully]
[2024-06-11 10:28:37,294: INFO: common: yaml file: params.yaml loaded successfully]
[2024-06-11 10:28:37,294: INFO: common: created directory at: artifacts]
[2024-06-11 10:28:37,295: INFO: common: created directory at: artifacts/data_transformation]
[2024-06-11 10:28:48,253: INFO: main: >>>>>> stage Data Transformation stage completed <<<<<<

x==========x]
[2024-06-11 22:49:35,991: INFO: utils: NumExpr defaulting to 4 threads.]
[2024-06-11 22:50:30,201: INFO: utils: NumExpr defaulting to 4 threads.]
[2024-06-11 22:53:48,029: INFO: utils: NumExpr defaulting to 4 threads.]
[2024-06-11 22:54:01,986: INFO: main: >>>>>> stage Data Ingestion stage started <<<<<<]
[2024-06-11 22:54:02,004: INFO: common: yaml file: config\config.yaml loaded successfully]
[2024-06-11 22:54:02,014: INFO: common: yaml file: params.yaml loaded successfully]
[2024-06-11 22:54:02,015: INFO: common: created directory at: artifacts]
[2024-06-11 22:54:02,016: INFO: common: created directory at: artifacts/data_ingestion]
[2024-06-11 22:54:02,018: INFO: data_ingestion: File already exists of size: ~ 7718 KB]
[2024-06-11 22:54:02,215: INFO: main: >>>>>> stage Data Ingestion stage completed <<<<<<

x==========x]
[2024-06-11 22:54:02,216: INFO: main: >>>>>> stage Data Validation stage started <<<<<<]
[2024-06-11 22:54:02,218: INFO: common: yaml file: config\config.yaml loaded successfully]
[2024-06-11 22:54:02,220: INFO: common: yaml file: params.yaml loaded successfully]
[2024-06-11 22:54:02,221: INFO: common: created directory at: artifacts]
[2024-06-11 22:54:02,221: INFO: common: created directory at: artifacts/data_validation]
[2024-06-11 22:54:02,225: INFO: main: >>>>>> stage Data Validation stage completed <<<<<<

x==========x]
[2024-06-11 22:54:02,228: INFO: main: >>>>>> stage Data Transformation stage started <<<<<<]
[2024-06-11 22:54:02,234: INFO: common: yaml file: config\config.yaml loaded successfully]
[2024-06-11 22:54:02,235: INFO: common: yaml file: params.yaml loaded successfully]
[2024-06-11 22:54:02,236: INFO: common: created directory at: artifacts]
[2024-06-11 22:54:02,236: INFO: common: created directory at: artifacts/data_transformation]
[2024-06-11 22:54:04,636: WARNING: arrow_dataset: Loading cached processed dataset at C:\Users\Anoop Maurya\Documents\GitHub\End-To-End-NLP-Project-Implementation-With-Deployment-Github-Action\artifacts\data_ingestion\samsum_dataset\train\cache-ba20fc51455005bb.arrow]
[2024-06-11 22:54:05,375: WARNING: arrow_dataset: Loading cached processed dataset at C:\Users\Anoop Maurya\Documents\GitHub\End-To-End-NLP-Project-Implementation-With-Deployment-Github-Action\artifacts\data_ingestion\samsum_dataset\validation\cache-618fbcead4c97214.arrow]
[2024-06-11 22:54:05,560: INFO: main: >>>>>> stage Data Transformation stage completed <<<<<<

x==========x]
[2024-06-11 22:54:05,561: INFO: main: *******************]
[2024-06-11 22:54:05,563: INFO: main: >>>>>> stage Model Trainer stage started <<<<<<]
[2024-06-11 22:54:05,569: INFO: common: yaml file: config\config.yaml loaded successfully]
[2024-06-11 22:54:05,572: INFO: common: yaml file: params.yaml loaded successfully]
[2024-06-11 22:54:05,573: INFO: common: created directory at: artifacts]
[2024-06-11 22:54:05,574: ERROR: main: "'ConfigBox' object has no attribute 'model_trainer'"]
Traceback (most recent call last):
  File "C:\Users\Anoop Maurya\AppData\Roaming\Python\Python311\site-packages\box\box.py", line 503, in __getitem__
    return super().__getitem__(item)
           ^^^^^^^^^^^^^^^^^^^^^^^^^
KeyError: 'model_trainer'

The above exception was the direct cause of the following exception:

Traceback (most recent call last):
  File "C:\Users\Anoop Maurya\AppData\Roaming\Python\Python311\site-packages\box\box.py", line 536, in __getattr__
    value = self.__getitem__(item, _ignore_default=True)
            ^^^^^^^^^^^^^^^^^^^^^^^^^^^^^^^^^^^^^^^^^^^^
  File "C:\Users\Anoop Maurya\AppData\Roaming\Python\Python311\site-packages\box\box.py", line 524, in __getitem__
    raise BoxKeyError(str(err)) from _exception_cause(err)
box.exceptions.BoxKeyError: "'model_trainer'"

During handling of the above exception, another exception occurred:

Traceback (most recent call last):
  File "C:\Users\Anoop Maurya\AppData\Roaming\Python\Python311\site-packages\box\box.py", line 538, in __getattr__
    value = object.__getattribute__(self, item)
            ^^^^^^^^^^^^^^^^^^^^^^^^^^^^^^^^^^^
AttributeError: 'ConfigBox' object has no attribute 'model_trainer'

The above exception was the direct cause of the following exception:

Traceback (most recent call last):
  File "C:\Users\Anoop Maurya\AppData\Roaming\Python\Python311\site-packages\box\config_box.py", line 28, in __getattr__
    return super().__getattr__(item)
           ^^^^^^^^^^^^^^^^^^^^^^^^^
  File "C:\Users\Anoop Maurya\AppData\Roaming\Python\Python311\site-packages\box\box.py", line 552, in __getattr__
    raise BoxKeyError(str(err)) from _exception_cause(err)
box.exceptions.BoxKeyError: "'ConfigBox' object has no attribute 'model_trainer'"

During handling of the above exception, another exception occurred:

Traceback (most recent call last):
  File "C:\Users\Anoop Maurya\AppData\Roaming\Python\Python311\site-packages\box\box.py", line 503, in __getitem__
    return super().__getitem__(item)
           ^^^^^^^^^^^^^^^^^^^^^^^^^
KeyError: 'model_trainer'

The above exception was the direct cause of the following exception:

Traceback (most recent call last):
  File "C:\Users\Anoop Maurya\AppData\Roaming\Python\Python311\site-packages\box\box.py", line 536, in __getattr__
    value = self.__getitem__(item, _ignore_default=True)
            ^^^^^^^^^^^^^^^^^^^^^^^^^^^^^^^^^^^^^^^^^^^^
  File "C:\Users\Anoop Maurya\AppData\Roaming\Python\Python311\site-packages\box\box.py", line 524, in __getitem__
    raise BoxKeyError(str(err)) from _exception_cause(err)
box.exceptions.BoxKeyError: "'model_trainer'"

During handling of the above exception, another exception occurred:

Traceback (most recent call last):
  File "C:\Users\Anoop Maurya\AppData\Roaming\Python\Python311\site-packages\box\box.py", line 538, in __getattr__
    value = object.__getattribute__(self, item)
            ^^^^^^^^^^^^^^^^^^^^^^^^^^^^^^^^^^^
AttributeError: 'ConfigBox' object has no attribute 'model_trainer'

The above exception was the direct cause of the following exception:

Traceback (most recent call last):
  File "c:\Users\Anoop Maurya\Documents\GitHub\End-To-End-NLP-Project-Implementation-With-Deployment-Github-Action\main.py", line 49, in <module>
    model_trainer.main()
  File "c:\users\anoop maurya\documents\github\end-to-end-nlp-project-implementation-with-deployment-github-action\src\textSummarizer\pipeline\stage_04_model_trainer.py", line 12, in main
    model_trainer_config = config.get_model_trainer_config()
                           ^^^^^^^^^^^^^^^^^^^^^^^^^^^^^^^^^
  File "c:\users\anoop maurya\documents\github\end-to-end-nlp-project-implementation-with-deployment-github-action\src\textSummarizer\config\configuration.py", line 67, in get_model_trainer_config
    config = self.config.model_trainer
             ^^^^^^^^^^^^^^^^^^^^^^^^^
  File "C:\Users\Anoop Maurya\AppData\Roaming\Python\Python311\site-packages\box\config_box.py", line 30, in __getattr__
    return super().__getattr__(item.lower())
           ^^^^^^^^^^^^^^^^^^^^^^^^^^^^^^^^^
  File "C:\Users\Anoop Maurya\AppData\Roaming\Python\Python311\site-packages\box\box.py", line 552, in __getattr__
    raise BoxKeyError(str(err)) from _exception_cause(err)
box.exceptions.BoxKeyError: "'ConfigBox' object has no attribute 'model_trainer'"
[2024-06-11 22:56:43,869: INFO: utils: NumExpr defaulting to 4 threads.]
[2024-06-11 22:56:53,255: INFO: main: >>>>>> stage Data Ingestion stage started <<<<<<]
[2024-06-11 22:56:53,260: INFO: common: yaml file: config\config.yaml loaded successfully]
[2024-06-11 22:56:53,261: INFO: common: yaml file: params.yaml loaded successfully]
[2024-06-11 22:56:53,262: INFO: common: created directory at: artifacts]
[2024-06-11 22:56:53,263: INFO: common: created directory at: artifacts/data_ingestion]
[2024-06-11 22:56:53,263: INFO: data_ingestion: File already exists of size: ~ 7718 KB]
[2024-06-11 22:56:53,445: INFO: main: >>>>>> stage Data Ingestion stage completed <<<<<<

x==========x]
[2024-06-11 22:56:53,446: INFO: main: >>>>>> stage Data Validation stage started <<<<<<]
[2024-06-11 22:56:53,449: INFO: common: yaml file: config\config.yaml loaded successfully]
[2024-06-11 22:56:53,451: INFO: common: yaml file: params.yaml loaded successfully]
[2024-06-11 22:56:53,453: INFO: common: created directory at: artifacts]
[2024-06-11 22:56:53,454: INFO: common: created directory at: artifacts/data_validation]
[2024-06-11 22:56:53,494: INFO: main: >>>>>> stage Data Validation stage completed <<<<<<

x==========x]
[2024-06-11 22:56:53,495: INFO: main: >>>>>> stage Data Transformation stage started <<<<<<]
[2024-06-11 22:56:53,503: INFO: common: yaml file: config\config.yaml loaded successfully]
[2024-06-11 22:56:53,507: INFO: common: yaml file: params.yaml loaded successfully]
[2024-06-11 22:56:53,508: INFO: common: created directory at: artifacts]
[2024-06-11 22:56:53,510: INFO: common: created directory at: artifacts/data_transformation]
[2024-06-11 22:56:56,051: WARNING: arrow_dataset: Loading cached processed dataset at C:\Users\Anoop Maurya\Documents\GitHub\End-To-End-NLP-Project-Implementation-With-Deployment-Github-Action\artifacts\data_ingestion\samsum_dataset\train\cache-ba20fc51455005bb.arrow]
[2024-06-11 22:56:56,125: WARNING: arrow_dataset: Loading cached processed dataset at C:\Users\Anoop Maurya\Documents\GitHub\End-To-End-NLP-Project-Implementation-With-Deployment-Github-Action\artifacts\data_ingestion\samsum_dataset\test\cache-9a7bbc0fd377bfb6.arrow]
[2024-06-11 22:56:57,242: INFO: main: >>>>>> stage Data Transformation stage completed <<<<<<

x==========x]
[2024-06-11 22:56:57,243: INFO: main: *******************]
[2024-06-11 22:56:57,243: INFO: main: >>>>>> stage Model Trainer stage started <<<<<<]
[2024-06-11 22:56:57,249: INFO: common: yaml file: config\config.yaml loaded successfully]
[2024-06-11 22:56:57,253: INFO: common: yaml file: params.yaml loaded successfully]
[2024-06-11 22:56:57,255: INFO: common: created directory at: artifacts]
[2024-06-11 22:56:57,256: ERROR: main: "'ConfigBox' object has no attribute 'model_trainer'"]
Traceback (most recent call last):
  File "C:\Users\Anoop Maurya\AppData\Roaming\Python\Python311\site-packages\box\box.py", line 503, in __getitem__
    return super().__getitem__(item)
           ^^^^^^^^^^^^^^^^^^^^^^^^^
KeyError: 'model_trainer'

The above exception was the direct cause of the following exception:

Traceback (most recent call last):
  File "C:\Users\Anoop Maurya\AppData\Roaming\Python\Python311\site-packages\box\box.py", line 536, in __getattr__
    value = self.__getitem__(item, _ignore_default=True)
            ^^^^^^^^^^^^^^^^^^^^^^^^^^^^^^^^^^^^^^^^^^^^
  File "C:\Users\Anoop Maurya\AppData\Roaming\Python\Python311\site-packages\box\box.py", line 524, in __getitem__
    raise BoxKeyError(str(err)) from _exception_cause(err)
box.exceptions.BoxKeyError: "'model_trainer'"

During handling of the above exception, another exception occurred:

Traceback (most recent call last):
  File "C:\Users\Anoop Maurya\AppData\Roaming\Python\Python311\site-packages\box\box.py", line 538, in __getattr__
    value = object.__getattribute__(self, item)
            ^^^^^^^^^^^^^^^^^^^^^^^^^^^^^^^^^^^
AttributeError: 'ConfigBox' object has no attribute 'model_trainer'

The above exception was the direct cause of the following exception:

Traceback (most recent call last):
  File "C:\Users\Anoop Maurya\AppData\Roaming\Python\Python311\site-packages\box\config_box.py", line 28, in __getattr__
    return super().__getattr__(item)
           ^^^^^^^^^^^^^^^^^^^^^^^^^
  File "C:\Users\Anoop Maurya\AppData\Roaming\Python\Python311\site-packages\box\box.py", line 552, in __getattr__
    raise BoxKeyError(str(err)) from _exception_cause(err)
box.exceptions.BoxKeyError: "'ConfigBox' object has no attribute 'model_trainer'"

During handling of the above exception, another exception occurred:

Traceback (most recent call last):
  File "C:\Users\Anoop Maurya\AppData\Roaming\Python\Python311\site-packages\box\box.py", line 503, in __getitem__
    return super().__getitem__(item)
           ^^^^^^^^^^^^^^^^^^^^^^^^^
KeyError: 'model_trainer'

The above exception was the direct cause of the following exception:

Traceback (most recent call last):
  File "C:\Users\Anoop Maurya\AppData\Roaming\Python\Python311\site-packages\box\box.py", line 536, in __getattr__
    value = self.__getitem__(item, _ignore_default=True)
            ^^^^^^^^^^^^^^^^^^^^^^^^^^^^^^^^^^^^^^^^^^^^
  File "C:\Users\Anoop Maurya\AppData\Roaming\Python\Python311\site-packages\box\box.py", line 524, in __getitem__
    raise BoxKeyError(str(err)) from _exception_cause(err)
box.exceptions.BoxKeyError: "'model_trainer'"

During handling of the above exception, another exception occurred:

Traceback (most recent call last):
  File "C:\Users\Anoop Maurya\AppData\Roaming\Python\Python311\site-packages\box\box.py", line 538, in __getattr__
    value = object.__getattribute__(self, item)
            ^^^^^^^^^^^^^^^^^^^^^^^^^^^^^^^^^^^
AttributeError: 'ConfigBox' object has no attribute 'model_trainer'

The above exception was the direct cause of the following exception:

Traceback (most recent call last):
  File "c:\Users\Anoop Maurya\Documents\GitHub\End-To-End-NLP-Project-Implementation-With-Deployment-Github-Action\main.py", line 49, in <module>
    model_trainer.main()
  File "c:\users\anoop maurya\documents\github\end-to-end-nlp-project-implementation-with-deployment-github-action\src\textSummarizer\pipeline\stage_04_model_trainer.py", line 12, in main
    model_trainer_config = config.get_model_trainer_config()
                           ^^^^^^^^^^^^^^^^^^^^^^^^^^^^^^^^^
  File "c:\users\anoop maurya\documents\github\end-to-end-nlp-project-implementation-with-deployment-github-action\src\textSummarizer\config\configuration.py", line 67, in get_model_trainer_config
    config = self.config.model_trainer
             ^^^^^^^^^^^^^^^^^^^^^^^^^
  File "C:\Users\Anoop Maurya\AppData\Roaming\Python\Python311\site-packages\box\config_box.py", line 30, in __getattr__
    return super().__getattr__(item.lower())
           ^^^^^^^^^^^^^^^^^^^^^^^^^^^^^^^^^
  File "C:\Users\Anoop Maurya\AppData\Roaming\Python\Python311\site-packages\box\box.py", line 552, in __getattr__
    raise BoxKeyError(str(err)) from _exception_cause(err)
box.exceptions.BoxKeyError: "'ConfigBox' object has no attribute 'model_trainer'"
[2024-06-11 22:58:00,479: INFO: utils: NumExpr defaulting to 4 threads.]
[2024-06-11 22:58:07,756: INFO: main: >>>>>> stage Data Ingestion stage started <<<<<<]
[2024-06-11 22:58:07,758: INFO: common: yaml file: config\config.yaml loaded successfully]
[2024-06-11 22:58:07,760: INFO: common: yaml file: params.yaml loaded successfully]
[2024-06-11 22:58:07,761: INFO: common: created directory at: artifacts]
[2024-06-11 22:58:07,761: INFO: common: created directory at: artifacts/data_ingestion]
[2024-06-11 22:58:07,762: INFO: data_ingestion: File already exists of size: ~ 7718 KB]
[2024-06-11 22:58:07,890: INFO: main: >>>>>> stage Data Ingestion stage completed <<<<<<

x==========x]
[2024-06-11 22:58:07,891: INFO: main: >>>>>> stage Data Validation stage started <<<<<<]
[2024-06-11 22:58:07,894: INFO: common: yaml file: config\config.yaml loaded successfully]
[2024-06-11 22:58:07,896: INFO: common: yaml file: params.yaml loaded successfully]
[2024-06-11 22:58:07,897: INFO: common: created directory at: artifacts]
[2024-06-11 22:58:07,898: INFO: common: created directory at: artifacts/data_validation]
[2024-06-11 22:58:07,902: INFO: main: >>>>>> stage Data Validation stage completed <<<<<<

x==========x]
[2024-06-11 22:58:07,903: INFO: main: >>>>>> stage Data Transformation stage started <<<<<<]
[2024-06-11 22:58:07,911: INFO: common: yaml file: config\config.yaml loaded successfully]
[2024-06-11 22:58:07,916: INFO: common: yaml file: params.yaml loaded successfully]
[2024-06-11 22:58:07,917: INFO: common: created directory at: artifacts]
[2024-06-11 22:58:07,917: INFO: common: created directory at: artifacts/data_transformation]
[2024-06-11 22:58:09,517: WARNING: arrow_dataset: Loading cached processed dataset at C:\Users\Anoop Maurya\Documents\GitHub\End-To-End-NLP-Project-Implementation-With-Deployment-Github-Action\artifacts\data_ingestion\samsum_dataset\train\cache-ba20fc51455005bb.arrow]
[2024-06-11 22:58:09,533: WARNING: arrow_dataset: Loading cached processed dataset at C:\Users\Anoop Maurya\Documents\GitHub\End-To-End-NLP-Project-Implementation-With-Deployment-Github-Action\artifacts\data_ingestion\samsum_dataset\test\cache-9a7bbc0fd377bfb6.arrow]
[2024-06-11 22:58:09,559: WARNING: arrow_dataset: Loading cached processed dataset at C:\Users\Anoop Maurya\Documents\GitHub\End-To-End-NLP-Project-Implementation-With-Deployment-Github-Action\artifacts\data_ingestion\samsum_dataset\validation\cache-09e07b1835f4a5fa.arrow]
[2024-06-11 22:58:09,789: INFO: main: >>>>>> stage Data Transformation stage completed <<<<<<

x==========x]
[2024-06-11 22:58:09,790: INFO: main: *******************]
[2024-06-11 22:58:09,791: INFO: main: >>>>>> stage Model Trainer stage started <<<<<<]
[2024-06-11 22:58:09,795: INFO: common: yaml file: config\config.yaml loaded successfully]
[2024-06-11 22:58:09,815: INFO: common: yaml file: params.yaml loaded successfully]
[2024-06-11 22:58:09,819: INFO: common: created directory at: artifacts]
[2024-06-11 22:58:09,819: ERROR: main: "'ConfigBox' object has no attribute 'model_trainer'"]
Traceback (most recent call last):
  File "C:\Users\Anoop Maurya\AppData\Roaming\Python\Python311\site-packages\box\box.py", line 503, in __getitem__
    return super().__getitem__(item)
           ^^^^^^^^^^^^^^^^^^^^^^^^^
KeyError: 'model_trainer'

The above exception was the direct cause of the following exception:

Traceback (most recent call last):
  File "C:\Users\Anoop Maurya\AppData\Roaming\Python\Python311\site-packages\box\box.py", line 536, in __getattr__
    value = self.__getitem__(item, _ignore_default=True)
            ^^^^^^^^^^^^^^^^^^^^^^^^^^^^^^^^^^^^^^^^^^^^
  File "C:\Users\Anoop Maurya\AppData\Roaming\Python\Python311\site-packages\box\box.py", line 524, in __getitem__
    raise BoxKeyError(str(err)) from _exception_cause(err)
box.exceptions.BoxKeyError: "'model_trainer'"

During handling of the above exception, another exception occurred:

Traceback (most recent call last):
  File "C:\Users\Anoop Maurya\AppData\Roaming\Python\Python311\site-packages\box\box.py", line 538, in __getattr__
    value = object.__getattribute__(self, item)
            ^^^^^^^^^^^^^^^^^^^^^^^^^^^^^^^^^^^
AttributeError: 'ConfigBox' object has no attribute 'model_trainer'

The above exception was the direct cause of the following exception:

Traceback (most recent call last):
  File "C:\Users\Anoop Maurya\AppData\Roaming\Python\Python311\site-packages\box\config_box.py", line 28, in __getattr__
    return super().__getattr__(item)
           ^^^^^^^^^^^^^^^^^^^^^^^^^
  File "C:\Users\Anoop Maurya\AppData\Roaming\Python\Python311\site-packages\box\box.py", line 552, in __getattr__
    raise BoxKeyError(str(err)) from _exception_cause(err)
box.exceptions.BoxKeyError: "'ConfigBox' object has no attribute 'model_trainer'"

During handling of the above exception, another exception occurred:

Traceback (most recent call last):
  File "C:\Users\Anoop Maurya\AppData\Roaming\Python\Python311\site-packages\box\box.py", line 503, in __getitem__
    return super().__getitem__(item)
           ^^^^^^^^^^^^^^^^^^^^^^^^^
KeyError: 'model_trainer'

The above exception was the direct cause of the following exception:

Traceback (most recent call last):
  File "C:\Users\Anoop Maurya\AppData\Roaming\Python\Python311\site-packages\box\box.py", line 536, in __getattr__
    value = self.__getitem__(item, _ignore_default=True)
            ^^^^^^^^^^^^^^^^^^^^^^^^^^^^^^^^^^^^^^^^^^^^
  File "C:\Users\Anoop Maurya\AppData\Roaming\Python\Python311\site-packages\box\box.py", line 524, in __getitem__
    raise BoxKeyError(str(err)) from _exception_cause(err)
box.exceptions.BoxKeyError: "'model_trainer'"

During handling of the above exception, another exception occurred:

Traceback (most recent call last):
  File "C:\Users\Anoop Maurya\AppData\Roaming\Python\Python311\site-packages\box\box.py", line 538, in __getattr__
    value = object.__getattribute__(self, item)
            ^^^^^^^^^^^^^^^^^^^^^^^^^^^^^^^^^^^
AttributeError: 'ConfigBox' object has no attribute 'model_trainer'

The above exception was the direct cause of the following exception:

Traceback (most recent call last):
  File "c:\Users\Anoop Maurya\Documents\GitHub\End-To-End-NLP-Project-Implementation-With-Deployment-Github-Action\main.py", line 49, in <module>
    model_trainer.main()
  File "c:\users\anoop maurya\documents\github\end-to-end-nlp-project-implementation-with-deployment-github-action\src\textSummarizer\pipeline\stage_04_model_trainer.py", line 12, in main
    model_trainer_config = config.get_model_trainer_config()
                           ^^^^^^^^^^^^^^^^^^^^^^^^^^^^^^^^^
  File "c:\users\anoop maurya\documents\github\end-to-end-nlp-project-implementation-with-deployment-github-action\src\textSummarizer\config\configuration.py", line 67, in get_model_trainer_config
    config = self.config.model_trainer
             ^^^^^^^^^^^^^^^^^^^^^^^^^
  File "C:\Users\Anoop Maurya\AppData\Roaming\Python\Python311\site-packages\box\config_box.py", line 30, in __getattr__
    return super().__getattr__(item.lower())
           ^^^^^^^^^^^^^^^^^^^^^^^^^^^^^^^^^
  File "C:\Users\Anoop Maurya\AppData\Roaming\Python\Python311\site-packages\box\box.py", line 552, in __getattr__
    raise BoxKeyError(str(err)) from _exception_cause(err)
box.exceptions.BoxKeyError: "'ConfigBox' object has no attribute 'model_trainer'"
[2024-06-11 23:03:57,359: INFO: utils: NumExpr defaulting to 4 threads.]
[2024-06-11 23:04:05,214: INFO: main: >>>>>> stage Data Ingestion stage started <<<<<<]
[2024-06-11 23:04:05,218: INFO: common: yaml file: config\config.yaml loaded successfully]
[2024-06-11 23:04:05,222: INFO: common: yaml file: params.yaml loaded successfully]
[2024-06-11 23:04:05,223: INFO: common: created directory at: artifacts]
[2024-06-11 23:04:05,224: INFO: common: created directory at: artifacts/data_ingestion]
[2024-06-11 23:04:05,224: INFO: data_ingestion: File already exists of size: ~ 7718 KB]
[2024-06-11 23:04:05,357: INFO: main: >>>>>> stage Data Ingestion stage completed <<<<<<

x==========x]
[2024-06-11 23:04:05,357: INFO: main: >>>>>> stage Data Validation stage started <<<<<<]
[2024-06-11 23:04:05,360: INFO: common: yaml file: config\config.yaml loaded successfully]
[2024-06-11 23:04:05,362: INFO: common: yaml file: params.yaml loaded successfully]
[2024-06-11 23:04:05,362: INFO: common: created directory at: artifacts]
[2024-06-11 23:04:05,363: INFO: common: created directory at: artifacts/data_validation]
[2024-06-11 23:04:05,365: INFO: main: >>>>>> stage Data Validation stage completed <<<<<<

x==========x]
[2024-06-11 23:04:05,365: INFO: main: >>>>>> stage Data Transformation stage started <<<<<<]
[2024-06-11 23:04:05,367: INFO: common: yaml file: config\config.yaml loaded successfully]
[2024-06-11 23:04:05,369: INFO: common: yaml file: params.yaml loaded successfully]
[2024-06-11 23:04:05,370: INFO: common: created directory at: artifacts]
[2024-06-11 23:04:05,370: INFO: common: created directory at: artifacts/data_transformation]
[2024-06-11 23:04:07,369: WARNING: arrow_dataset: Loading cached processed dataset at C:\Users\Anoop Maurya\Documents\GitHub\End-To-End-NLP-Project-Implementation-With-Deployment-Github-Action\artifacts\data_ingestion\samsum_dataset\train\cache-ba20fc51455005bb.arrow]
[2024-06-11 23:04:07,398: WARNING: arrow_dataset: Loading cached processed dataset at C:\Users\Anoop Maurya\Documents\GitHub\End-To-End-NLP-Project-Implementation-With-Deployment-Github-Action\artifacts\data_ingestion\samsum_dataset\test\cache-9a7bbc0fd377bfb6.arrow]
[2024-06-11 23:04:07,431: WARNING: arrow_dataset: Loading cached processed dataset at C:\Users\Anoop Maurya\Documents\GitHub\End-To-End-NLP-Project-Implementation-With-Deployment-Github-Action\artifacts\data_ingestion\samsum_dataset\validation\cache-09e07b1835f4a5fa.arrow]
[2024-06-11 23:04:07,603: INFO: main: >>>>>> stage Data Transformation stage completed <<<<<<

x==========x]
[2024-06-11 23:04:07,604: INFO: main: *******************]
[2024-06-11 23:04:07,605: INFO: main: >>>>>> stage Model Trainer stage started <<<<<<]
[2024-06-11 23:04:07,608: INFO: common: yaml file: config\config.yaml loaded successfully]
[2024-06-11 23:04:07,612: INFO: common: yaml file: params.yaml loaded successfully]
[2024-06-11 23:04:07,613: INFO: common: created directory at: artifacts]
[2024-06-11 23:04:07,614: ERROR: main: "'ConfigBox' object has no attribute 'model_trainer'"]
Traceback (most recent call last):
  File "box\\box.py", line 592, in box.box.Box.__getitem__
KeyError: 'model_trainer'

The above exception was the direct cause of the following exception:

Traceback (most recent call last):
  File "box\\box.py", line 631, in box.box.Box.__getattr__
  File "box\\box.py", line 619, in box.box.Box.__getitem__
box.exceptions.BoxKeyError: "'model_trainer'"

During handling of the above exception, another exception occurred:

Traceback (most recent call last):
  File "box\\box.py", line 633, in box.box.Box.__getattr__
AttributeError: 'ConfigBox' object has no attribute 'model_trainer'

The above exception was the direct cause of the following exception:

Traceback (most recent call last):
  File "box\\config_box.py", line 29, in box.config_box.ConfigBox.__getattr__
  File "box\\box.py", line 647, in box.box.Box.__getattr__
box.exceptions.BoxKeyError: "'ConfigBox' object has no attribute 'model_trainer'"

During handling of the above exception, another exception occurred:

Traceback (most recent call last):
  File "box\\box.py", line 592, in box.box.Box.__getitem__
KeyError: 'model_trainer'

The above exception was the direct cause of the following exception:

Traceback (most recent call last):
  File "box\\box.py", line 631, in box.box.Box.__getattr__
  File "box\\box.py", line 619, in box.box.Box.__getitem__
box.exceptions.BoxKeyError: "'model_trainer'"

During handling of the above exception, another exception occurred:

Traceback (most recent call last):
  File "box\\box.py", line 633, in box.box.Box.__getattr__
AttributeError: 'ConfigBox' object has no attribute 'model_trainer'

The above exception was the direct cause of the following exception:

Traceback (most recent call last):
  File "c:\Users\Anoop Maurya\Documents\GitHub\End-To-End-NLP-Project-Implementation-With-Deployment-Github-Action\main.py", line 49, in <module>
    model_trainer.main()
  File "c:\users\anoop maurya\documents\github\end-to-end-nlp-project-implementation-with-deployment-github-action\src\textSummarizer\pipeline\stage_04_model_trainer.py", line 12, in main
    model_trainer_config = config.get_model_trainer_config()
                           ^^^^^^^^^^^^^^^^^^^^^^^^^^^^^^^^^
  File "c:\users\anoop maurya\documents\github\end-to-end-nlp-project-implementation-with-deployment-github-action\src\textSummarizer\config\configuration.py", line 67, in get_model_trainer_config
    config = self.config.model_trainer
             ^^^^^^^^^^^^^^^^^^^^^^^^^
  File "box\\config_box.py", line 31, in box.config_box.ConfigBox.__getattr__
  File "box\\box.py", line 647, in box.box.Box.__getattr__
box.exceptions.BoxKeyError: "'ConfigBox' object has no attribute 'model_trainer'"
[2024-06-11 23:09:18,856: INFO: utils: NumExpr defaulting to 4 threads.]
[2024-06-11 23:09:28,285: INFO: main: >>>>>> stage Data Ingestion stage started <<<<<<]
[2024-06-11 23:09:28,288: INFO: common: yaml file: config\config.yaml loaded successfully]
[2024-06-11 23:09:28,291: INFO: common: yaml file: params.yaml loaded successfully]
[2024-06-11 23:09:28,292: INFO: common: created directory at: artifacts]
[2024-06-11 23:09:28,292: INFO: common: created directory at: artifacts/data_ingestion]
[2024-06-11 23:09:28,293: INFO: data_ingestion: File already exists of size: ~ 7718 KB]
[2024-06-11 23:09:28,476: INFO: main: >>>>>> stage Data Ingestion stage completed <<<<<<

x==========x]
[2024-06-11 23:09:28,479: INFO: main: >>>>>> stage Data Validation stage started <<<<<<]
[2024-06-11 23:09:28,484: INFO: common: yaml file: config\config.yaml loaded successfully]
[2024-06-11 23:09:28,487: INFO: common: yaml file: params.yaml loaded successfully]
[2024-06-11 23:09:28,489: INFO: common: created directory at: artifacts]
[2024-06-11 23:09:28,489: INFO: common: created directory at: artifacts/data_validation]
[2024-06-11 23:09:28,497: INFO: main: >>>>>> stage Data Validation stage completed <<<<<<

x==========x]
[2024-06-11 23:09:28,501: INFO: main: >>>>>> stage Data Transformation stage started <<<<<<]
[2024-06-11 23:09:28,511: INFO: common: yaml file: config\config.yaml loaded successfully]
[2024-06-11 23:09:28,514: INFO: common: yaml file: params.yaml loaded successfully]
[2024-06-11 23:09:28,516: INFO: common: created directory at: artifacts]
[2024-06-11 23:09:28,517: INFO: common: created directory at: artifacts/data_transformation]
[2024-06-11 23:09:30,107: WARNING: arrow_dataset: Loading cached processed dataset at C:\Users\Anoop Maurya\Documents\GitHub\End-To-End-NLP-Project-Implementation-With-Deployment-Github-Action\artifacts\data_ingestion\samsum_dataset\train\cache-ba20fc51455005bb.arrow]
[2024-06-11 23:09:30,125: WARNING: arrow_dataset: Loading cached processed dataset at C:\Users\Anoop Maurya\Documents\GitHub\End-To-End-NLP-Project-Implementation-With-Deployment-Github-Action\artifacts\data_ingestion\samsum_dataset\test\cache-9a7bbc0fd377bfb6.arrow]
[2024-06-11 23:09:30,152: WARNING: arrow_dataset: Loading cached processed dataset at C:\Users\Anoop Maurya\Documents\GitHub\End-To-End-NLP-Project-Implementation-With-Deployment-Github-Action\artifacts\data_ingestion\samsum_dataset\validation\cache-09e07b1835f4a5fa.arrow]
[2024-06-11 23:09:30,311: INFO: main: >>>>>> stage Data Transformation stage completed <<<<<<

x==========x]
[2024-06-11 23:09:30,312: INFO: main: *******************]
[2024-06-11 23:09:30,312: INFO: main: >>>>>> stage Model Trainer stage started <<<<<<]
[2024-06-11 23:09:30,322: INFO: common: yaml file: config\config.yaml loaded successfully]
[2024-06-11 23:09:30,328: INFO: common: yaml file: params.yaml loaded successfully]
[2024-06-11 23:09:30,329: INFO: common: created directory at: artifacts]
[2024-06-11 23:09:30,330: INFO: common: created directory at: artifacts/model_trainer]
[2024-06-11 23:13:48,791: ERROR: main: 'NoneType' object has no attribute 'split']
Traceback (most recent call last):
  File "c:\Users\Anoop Maurya\Documents\GitHub\End-To-End-NLP-Project-Implementation-With-Deployment-Github-Action\main.py", line 49, in <module>
    model_trainer.main()
  File "c:\users\anoop maurya\documents\github\end-to-end-nlp-project-implementation-with-deployment-github-action\src\textSummarizer\pipeline\stage_04_model_trainer.py", line 14, in main
    model_trainer_config.train()
  File "c:\users\anoop maurya\documents\github\end-to-end-nlp-project-implementation-with-deployment-github-action\src\textSummarizer\components\model_trainer.py", line 39, in train
    trainer.train()
  File "C:\Users\Anoop Maurya\AppData\Roaming\Python\Python311\site-packages\transformers\trainer.py", line 1555, in train
    return inner_training_loop(
           ^^^^^^^^^^^^^^^^^^^^
  File "C:\Users\Anoop Maurya\AppData\Roaming\Python\Python311\site-packages\transformers\trainer.py", line 1789, in _inner_training_loop
    self.control = self.callback_handler.on_train_begin(args, self.state, self.control)
                   ^^^^^^^^^^^^^^^^^^^^^^^^^^^^^^^^^^^^^^^^^^^^^^^^^^^^^^^^^^^^^^^^^^^^
  File "C:\Users\Anoop Maurya\AppData\Roaming\Python\Python311\site-packages\transformers\trainer_callback.py", line 363, in on_train_begin
    return self.call_event("on_train_begin", args, state, control)
           ^^^^^^^^^^^^^^^^^^^^^^^^^^^^^^^^^^^^^^^^^^^^^^^^^^^^^^^
  File "C:\Users\Anoop Maurya\AppData\Roaming\Python\Python311\site-packages\transformers\trainer_callback.py", line 407, in call_event
    result = getattr(callback, event)(
             ^^^^^^^^^^^^^^^^^^^^^^^^^
  File "C:\Users\Anoop Maurya\AppData\Roaming\Python\Python311\site-packages\transformers\integrations\integration_utils.py", line 1020, in on_train_begin
    self.setup(args, state, model)
  File "C:\Users\Anoop Maurya\AppData\Roaming\Python\Python311\site-packages\transformers\integrations\integration_utils.py", line 1091, in setup
    owner=self.remote.split(os.sep)[-2],
          ^^^^^^^^^^^^^^^^^
AttributeError: 'NoneType' object has no attribute 'split'
[2024-06-11 23:16:40,610: INFO: utils: NumExpr defaulting to 4 threads.]
[2024-06-11 23:17:06,457: INFO: main: >>>>>> stage Data Ingestion stage started <<<<<<]
[2024-06-11 23:17:06,463: INFO: common: yaml file: config\config.yaml loaded successfully]
[2024-06-11 23:17:06,465: INFO: common: yaml file: params.yaml loaded successfully]
[2024-06-11 23:17:06,466: INFO: common: created directory at: artifacts]
[2024-06-11 23:17:06,467: INFO: common: created directory at: artifacts/data_ingestion]
[2024-06-11 23:17:06,468: INFO: data_ingestion: File already exists of size: ~ 7718 KB]
[2024-06-11 23:17:06,802: INFO: main: >>>>>> stage Data Ingestion stage completed <<<<<<

x==========x]
[2024-06-11 23:17:06,803: INFO: main: >>>>>> stage Data Validation stage started <<<<<<]
[2024-06-11 23:17:06,815: INFO: common: yaml file: config\config.yaml loaded successfully]
[2024-06-11 23:17:06,823: INFO: common: yaml file: params.yaml loaded successfully]
[2024-06-11 23:17:06,824: INFO: common: created directory at: artifacts]
[2024-06-11 23:17:06,825: INFO: common: created directory at: artifacts/data_validation]
[2024-06-11 23:17:06,830: INFO: main: >>>>>> stage Data Validation stage completed <<<<<<

x==========x]
[2024-06-11 23:17:06,831: INFO: main: >>>>>> stage Data Transformation stage started <<<<<<]
[2024-06-11 23:17:06,840: INFO: common: yaml file: config\config.yaml loaded successfully]
[2024-06-11 23:17:06,842: INFO: common: yaml file: params.yaml loaded successfully]
[2024-06-11 23:17:06,843: INFO: common: created directory at: artifacts]
[2024-06-11 23:17:06,844: INFO: common: created directory at: artifacts/data_transformation]
[2024-06-11 23:17:10,211: WARNING: arrow_dataset: Loading cached processed dataset at C:\Users\Anoop Maurya\Documents\GitHub\End-To-End-NLP-Project-Implementation-With-Deployment-Github-Action\artifacts\data_ingestion\samsum_dataset\train\cache-ba20fc51455005bb.arrow]
[2024-06-11 23:17:10,238: WARNING: arrow_dataset: Loading cached processed dataset at C:\Users\Anoop Maurya\Documents\GitHub\End-To-End-NLP-Project-Implementation-With-Deployment-Github-Action\artifacts\data_ingestion\samsum_dataset\test\cache-9a7bbc0fd377bfb6.arrow]
[2024-06-11 23:17:10,398: WARNING: arrow_dataset: Loading cached processed dataset at C:\Users\Anoop Maurya\Documents\GitHub\End-To-End-NLP-Project-Implementation-With-Deployment-Github-Action\artifacts\data_ingestion\samsum_dataset\validation\cache-09e07b1835f4a5fa.arrow]
[2024-06-11 23:17:10,608: INFO: main: >>>>>> stage Data Transformation stage completed <<<<<<

x==========x]
[2024-06-11 23:17:10,609: INFO: main: *******************]
[2024-06-11 23:17:10,609: INFO: main: >>>>>> stage Model Trainer stage started <<<<<<]
[2024-06-11 23:17:10,615: INFO: common: yaml file: config\config.yaml loaded successfully]
[2024-06-11 23:17:10,620: INFO: common: yaml file: params.yaml loaded successfully]
[2024-06-11 23:17:10,621: INFO: common: created directory at: artifacts]
[2024-06-11 23:17:10,622: INFO: common: created directory at: artifacts/model_trainer]
[2024-06-11 23:18:05,160: ERROR: main: 'NoneType' object has no attribute 'split']
Traceback (most recent call last):
  File "c:\Users\Anoop Maurya\Documents\GitHub\End-To-End-NLP-Project-Implementation-With-Deployment-Github-Action\main.py", line 49, in <module>
    model_trainer.main()
  File "c:\users\anoop maurya\documents\github\end-to-end-nlp-project-implementation-with-deployment-github-action\src\textSummarizer\pipeline\stage_04_model_trainer.py", line 14, in main
    model_trainer_config.train()
  File "c:\users\anoop maurya\documents\github\end-to-end-nlp-project-implementation-with-deployment-github-action\src\textSummarizer\components\model_trainer.py", line 39, in train
    trainer.train()
  File "C:\Users\Anoop Maurya\AppData\Roaming\Python\Python311\site-packages\transformers\trainer.py", line 1555, in train
    return inner_training_loop(
           ^^^^^^^^^^^^^^^^^^^^
  File "C:\Users\Anoop Maurya\AppData\Roaming\Python\Python311\site-packages\transformers\trainer.py", line 1789, in _inner_training_loop
    self.control = self.callback_handler.on_train_begin(args, self.state, self.control)
                   ^^^^^^^^^^^^^^^^^^^^^^^^^^^^^^^^^^^^^^^^^^^^^^^^^^^^^^^^^^^^^^^^^^^^
  File "C:\Users\Anoop Maurya\AppData\Roaming\Python\Python311\site-packages\transformers\trainer_callback.py", line 363, in on_train_begin
    return self.call_event("on_train_begin", args, state, control)
           ^^^^^^^^^^^^^^^^^^^^^^^^^^^^^^^^^^^^^^^^^^^^^^^^^^^^^^^
  File "C:\Users\Anoop Maurya\AppData\Roaming\Python\Python311\site-packages\transformers\trainer_callback.py", line 407, in call_event
    result = getattr(callback, event)(
             ^^^^^^^^^^^^^^^^^^^^^^^^^
  File "C:\Users\Anoop Maurya\AppData\Roaming\Python\Python311\site-packages\transformers\integrations\integration_utils.py", line 1020, in on_train_begin
    self.setup(args, state, model)
  File "C:\Users\Anoop Maurya\AppData\Roaming\Python\Python311\site-packages\transformers\integrations\integration_utils.py", line 1091, in setup
    owner=self.remote.split(os.sep)[-2],
          ^^^^^^^^^^^^^^^^^
AttributeError: 'NoneType' object has no attribute 'split'
